ERROR:app:Exception on /imghash [GET]
Traceback (most recent call last):
  File "/usr/local/lib/python3.6/dist-packages/flask/app.py", line 2073, in wsgi_app
    response = self.full_dispatch_request()
  File "/usr/local/lib/python3.6/dist-packages/flask/app.py", line 1518, in full_dispatch_request
    rv = self.handle_user_exception(e)
  File "/usr/local/lib/python3.6/dist-packages/flask/app.py", line 1516, in full_dispatch_request
    rv = self.dispatch_request()
  File "/usr/local/lib/python3.6/dist-packages/flask/app.py", line 1502, in dispatch_request
    return self.ensure_sync(self.view_functions[rule.endpoint])(**req.view_args)
  File "/home/jochsankehl/pixelcanvas/1_0/app.py", line 62, in getImageUpdate
    return f'{getImageHash()}|{countVisitors()}'
  File "/home/jochsankehl/pixelcanvas/1_0/app.py", line 118, in countVisitors
    return len(open(visitor_log_filename, 'r').read().strip().split('\n'))
FileNotFoundError: [Errno 2] No such file or directory: 'logs/visitors.log'
ERROR:app:Exception on /imghash [GET]
Traceback (most recent call last):
  File "/usr/local/lib/python3.6/dist-packages/flask/app.py", line 2073, in wsgi_app
    response = self.full_dispatch_request()
  File "/usr/local/lib/python3.6/dist-packages/flask/app.py", line 1518, in full_dispatch_request
    rv = self.handle_user_exception(e)
  File "/usr/local/lib/python3.6/dist-packages/flask/app.py", line 1516, in full_dispatch_request
    rv = self.dispatch_request()
  File "/usr/local/lib/python3.6/dist-packages/flask/app.py", line 1502, in dispatch_request
    return self.ensure_sync(self.view_functions[rule.endpoint])(**req.view_args)
  File "/home/jochsankehl/pixelcanvas/1_0/app.py", line 62, in getImageUpdate
    return f'{getImageHash()}|{countVisitors()}'
  File "/home/jochsankehl/pixelcanvas/1_0/app.py", line 118, in countVisitors
    return len(open(visitor_log_filename, 'r').read().strip().split('\n'))
FileNotFoundError: [Errno 2] No such file or directory: 'logs/visitors.log'
ERROR:app:Exception on /imghash [GET]
Traceback (most recent call last):
  File "/usr/local/lib/python3.6/dist-packages/flask/app.py", line 2073, in wsgi_app
    response = self.full_dispatch_request()
  File "/usr/local/lib/python3.6/dist-packages/flask/app.py", line 1518, in full_dispatch_request
    rv = self.handle_user_exception(e)
  File "/usr/local/lib/python3.6/dist-packages/flask/app.py", line 1516, in full_dispatch_request
    rv = self.dispatch_request()
  File "/usr/local/lib/python3.6/dist-packages/flask/app.py", line 1502, in dispatch_request
    return self.ensure_sync(self.view_functions[rule.endpoint])(**req.view_args)
  File "/home/jochsankehl/pixelcanvas/1_0/app.py", line 62, in getImageUpdate
    return f'{getImageHash()}|{countVisitors()}'
  File "/home/jochsankehl/pixelcanvas/1_0/app.py", line 118, in countVisitors
    return len(open(visitor_log_filename, 'r').read().strip().split('\n'))
FileNotFoundError: [Errno 2] No such file or directory: 'logs/visitors.log'
ERROR:app:Exception on /imghash [GET]
Traceback (most recent call last):
  File "/usr/local/lib/python3.6/dist-packages/flask/app.py", line 2073, in wsgi_app
    response = self.full_dispatch_request()
  File "/usr/local/lib/python3.6/dist-packages/flask/app.py", line 1518, in full_dispatch_request
    rv = self.handle_user_exception(e)
  File "/usr/local/lib/python3.6/dist-packages/flask/app.py", line 1516, in full_dispatch_request
    rv = self.dispatch_request()
  File "/usr/local/lib/python3.6/dist-packages/flask/app.py", line 1502, in dispatch_request
    return self.ensure_sync(self.view_functions[rule.endpoint])(**req.view_args)
  File "/home/jochsankehl/pixelcanvas/1_0/app.py", line 62, in getImageUpdate
    return f'{getImageHash()}|{countVisitors()}'
  File "/home/jochsankehl/pixelcanvas/1_0/app.py", line 118, in countVisitors
    return len(open(visitor_log_filename, 'r').read().strip().split('\n'))
FileNotFoundError: [Errno 2] No such file or directory: 'logs/visitors.log'
ERROR:app:Exception on /imghash [GET]
Traceback (most recent call last):
  File "/usr/local/lib/python3.6/dist-packages/flask/app.py", line 2073, in wsgi_app
    response = self.full_dispatch_request()
  File "/usr/local/lib/python3.6/dist-packages/flask/app.py", line 1518, in full_dispatch_request
    rv = self.handle_user_exception(e)
  File "/usr/local/lib/python3.6/dist-packages/flask/app.py", line 1516, in full_dispatch_request
    rv = self.dispatch_request()
  File "/usr/local/lib/python3.6/dist-packages/flask/app.py", line 1502, in dispatch_request
    return self.ensure_sync(self.view_functions[rule.endpoint])(**req.view_args)
  File "/home/jochsankehl/pixelcanvas/1_0/app.py", line 62, in getImageUpdate
    return f'{getImageHash()}|{countVisitors()}'
  File "/home/jochsankehl/pixelcanvas/1_0/app.py", line 118, in countVisitors
    return len(open(visitor_log_filename, 'r').read().strip().split('\n'))
FileNotFoundError: [Errno 2] No such file or directory: 'logs/visitors.log'
ERROR:app:Exception on /imghash [GET]
Traceback (most recent call last):
  File "/usr/local/lib/python3.6/dist-packages/flask/app.py", line 2073, in wsgi_app
    response = self.full_dispatch_request()
  File "/usr/local/lib/python3.6/dist-packages/flask/app.py", line 1518, in full_dispatch_request
    rv = self.handle_user_exception(e)
  File "/usr/local/lib/python3.6/dist-packages/flask/app.py", line 1516, in full_dispatch_request
    rv = self.dispatch_request()
  File "/usr/local/lib/python3.6/dist-packages/flask/app.py", line 1502, in dispatch_request
    return self.ensure_sync(self.view_functions[rule.endpoint])(**req.view_args)
  File "/home/jochsankehl/pixelcanvas/1_0/app.py", line 62, in getImageUpdate
    return f'{getImageHash()}|{countVisitors()}'
  File "/home/jochsankehl/pixelcanvas/1_0/app.py", line 118, in countVisitors
    return len(open(visitor_log_filename, 'r').read().strip().split('\n'))
FileNotFoundError: [Errno 2] No such file or directory: 'logs/visitors.log'
ERROR:app:Exception on /imghash [GET]
Traceback (most recent call last):
  File "/usr/local/lib/python3.6/dist-packages/flask/app.py", line 2073, in wsgi_app
    response = self.full_dispatch_request()
  File "/usr/local/lib/python3.6/dist-packages/flask/app.py", line 1518, in full_dispatch_request
    rv = self.handle_user_exception(e)
  File "/usr/local/lib/python3.6/dist-packages/flask/app.py", line 1516, in full_dispatch_request
    rv = self.dispatch_request()
  File "/usr/local/lib/python3.6/dist-packages/flask/app.py", line 1502, in dispatch_request
    return self.ensure_sync(self.view_functions[rule.endpoint])(**req.view_args)
  File "/home/jochsankehl/pixelcanvas/1_0/app.py", line 62, in getImageUpdate
    return f'{getImageHash()}|{countVisitors()}'
  File "/home/jochsankehl/pixelcanvas/1_0/app.py", line 118, in countVisitors
    return len(open(visitor_log_filename, 'r').read().strip().split('\n'))
FileNotFoundError: [Errno 2] No such file or directory: 'logs/visitors.log'
ERROR:app:Exception on /imghash [GET]
Traceback (most recent call last):
  File "/usr/local/lib/python3.6/dist-packages/flask/app.py", line 2073, in wsgi_app
    response = self.full_dispatch_request()
  File "/usr/local/lib/python3.6/dist-packages/flask/app.py", line 1518, in full_dispatch_request
    rv = self.handle_user_exception(e)
  File "/usr/local/lib/python3.6/dist-packages/flask/app.py", line 1516, in full_dispatch_request
    rv = self.dispatch_request()
  File "/usr/local/lib/python3.6/dist-packages/flask/app.py", line 1502, in dispatch_request
    return self.ensure_sync(self.view_functions[rule.endpoint])(**req.view_args)
  File "/home/jochsankehl/pixelcanvas/1_0/app.py", line 62, in getImageUpdate
    return f'{getImageHash()}|{countVisitors()}'
  File "/home/jochsankehl/pixelcanvas/1_0/app.py", line 118, in countVisitors
    return len(open(visitor_log_filename, 'r').read().strip().split('\n'))
FileNotFoundError: [Errno 2] No such file or directory: 'logs/visitors.log'
ERROR:app:Exception on /imghash [GET]
Traceback (most recent call last):
  File "/usr/local/lib/python3.6/dist-packages/flask/app.py", line 2073, in wsgi_app
    response = self.full_dispatch_request()
  File "/usr/local/lib/python3.6/dist-packages/flask/app.py", line 1518, in full_dispatch_request
    rv = self.handle_user_exception(e)
  File "/usr/local/lib/python3.6/dist-packages/flask/app.py", line 1516, in full_dispatch_request
    rv = self.dispatch_request()
  File "/usr/local/lib/python3.6/dist-packages/flask/app.py", line 1502, in dispatch_request
    return self.ensure_sync(self.view_functions[rule.endpoint])(**req.view_args)
  File "/home/jochsankehl/pixelcanvas/1_0/app.py", line 62, in getImageUpdate
    return f'{getImageHash()}|{countVisitors()}'
  File "/home/jochsankehl/pixelcanvas/1_0/app.py", line 118, in countVisitors
    return len(open(visitor_log_filename, 'r').read().strip().split('\n'))
FileNotFoundError: [Errno 2] No such file or directory: 'logs/visitors.log'
ERROR:root:LogVisitor:70.187.33.249:[Errno 2] No such file or directory: 'logs/visitors.log':None
ERROR:app:Exception on / [GET]
Traceback (most recent call last):
  File "/usr/local/lib/python3.6/dist-packages/flask/app.py", line 2073, in wsgi_app
    response = self.full_dispatch_request()
  File "/usr/local/lib/python3.6/dist-packages/flask/app.py", line 1518, in full_dispatch_request
    rv = self.handle_user_exception(e)
  File "/usr/local/lib/python3.6/dist-packages/flask/app.py", line 1516, in full_dispatch_request
    rv = self.dispatch_request()
  File "/usr/local/lib/python3.6/dist-packages/flask/app.py", line 1502, in dispatch_request
    return self.ensure_sync(self.view_functions[rule.endpoint])(**req.view_args)
  File "/home/jochsankehl/pixelcanvas/1_0/app.py", line 58, in index
    return render_template('index.html', x=x, y=y, color=color, visitors=countVisitors(), hash=getImageHash())
  File "/home/jochsankehl/pixelcanvas/1_0/app.py", line 118, in countVisitors
    return len(open(visitor_log_filename, 'r').read().strip().split('\n'))
FileNotFoundError: [Errno 2] No such file or directory: 'logs/visitors.log'
ERROR:app:Exception on /imghash [GET]
Traceback (most recent call last):
  File "/usr/local/lib/python3.6/dist-packages/flask/app.py", line 2073, in wsgi_app
    response = self.full_dispatch_request()
  File "/usr/local/lib/python3.6/dist-packages/flask/app.py", line 1518, in full_dispatch_request
    rv = self.handle_user_exception(e)
  File "/usr/local/lib/python3.6/dist-packages/flask/app.py", line 1516, in full_dispatch_request
    rv = self.dispatch_request()
  File "/usr/local/lib/python3.6/dist-packages/flask/app.py", line 1502, in dispatch_request
    return self.ensure_sync(self.view_functions[rule.endpoint])(**req.view_args)
  File "/home/jochsankehl/pixelcanvas/1_0/app.py", line 62, in getImageUpdate
    return f'{getImageHash()}|{countVisitors()}'
  File "/home/jochsankehl/pixelcanvas/1_0/app.py", line 118, in countVisitors
    return len(open(visitor_log_filename, 'r').read().strip().split('\n'))
FileNotFoundError: [Errno 2] No such file or directory: 'logs/visitors.log'
ERROR:root:LogVisitor:70.187.33.249:[Errno 2] No such file or directory: 'logs/visitors.log':None
ERROR:app:Exception on / [GET]
Traceback (most recent call last):
  File "/usr/local/lib/python3.6/dist-packages/flask/app.py", line 2073, in wsgi_app
    response = self.full_dispatch_request()
  File "/usr/local/lib/python3.6/dist-packages/flask/app.py", line 1518, in full_dispatch_request
    rv = self.handle_user_exception(e)
  File "/usr/local/lib/python3.6/dist-packages/flask/app.py", line 1516, in full_dispatch_request
    rv = self.dispatch_request()
  File "/usr/local/lib/python3.6/dist-packages/flask/app.py", line 1502, in dispatch_request
    return self.ensure_sync(self.view_functions[rule.endpoint])(**req.view_args)
  File "/home/jochsankehl/pixelcanvas/1_0/app.py", line 58, in index
    return render_template('index.html', x=x, y=y, color=color, visitors=countVisitors(), hash=getImageHash())
  File "/home/jochsankehl/pixelcanvas/1_0/app.py", line 118, in countVisitors
    return len(open(visitor_log_filename, 'r').read().strip().split('\n'))
FileNotFoundError: [Errno 2] No such file or directory: 'logs/visitors.log'
ERROR:app:Exception on /imghash [GET]
Traceback (most recent call last):
  File "/usr/local/lib/python3.6/dist-packages/flask/app.py", line 2073, in wsgi_app
    response = self.full_dispatch_request()
  File "/usr/local/lib/python3.6/dist-packages/flask/app.py", line 1518, in full_dispatch_request
    rv = self.handle_user_exception(e)
  File "/usr/local/lib/python3.6/dist-packages/flask/app.py", line 1516, in full_dispatch_request
    rv = self.dispatch_request()
  File "/usr/local/lib/python3.6/dist-packages/flask/app.py", line 1502, in dispatch_request
    return self.ensure_sync(self.view_functions[rule.endpoint])(**req.view_args)
  File "/home/jochsankehl/pixelcanvas/1_0/app.py", line 62, in getImageUpdate
    return f'{getImageHash()}|{countVisitors()}'
  File "/home/jochsankehl/pixelcanvas/1_0/app.py", line 118, in countVisitors
    return len(open(visitor_log_filename, 'r').read().strip().split('\n'))
FileNotFoundError: [Errno 2] No such file or directory: 'logs/visitors.log'
ERROR:root:LogVisitor:70.187.33.249:[Errno 2] No such file or directory: 'logs/visitors.log':None
ERROR:app:Exception on / [GET]
Traceback (most recent call last):
  File "/usr/local/lib/python3.6/dist-packages/flask/app.py", line 2073, in wsgi_app
    response = self.full_dispatch_request()
  File "/usr/local/lib/python3.6/dist-packages/flask/app.py", line 1518, in full_dispatch_request
    rv = self.handle_user_exception(e)
  File "/usr/local/lib/python3.6/dist-packages/flask/app.py", line 1516, in full_dispatch_request
    rv = self.dispatch_request()
  File "/usr/local/lib/python3.6/dist-packages/flask/app.py", line 1502, in dispatch_request
    return self.ensure_sync(self.view_functions[rule.endpoint])(**req.view_args)
  File "/home/jochsankehl/pixelcanvas/1_0/app.py", line 58, in index
    return render_template('index.html', x=x, y=y, color=color, visitors=countVisitors(), hash=getImageHash())
  File "/home/jochsankehl/pixelcanvas/1_0/app.py", line 118, in countVisitors
    return len(open(visitor_log_filename, 'r').read().strip().split('\n'))
FileNotFoundError: [Errno 2] No such file or directory: 'logs/visitors.log'
ERROR:app:Exception on /imghash [GET]
Traceback (most recent call last):
  File "/usr/local/lib/python3.6/dist-packages/flask/app.py", line 2073, in wsgi_app
    response = self.full_dispatch_request()
  File "/usr/local/lib/python3.6/dist-packages/flask/app.py", line 1518, in full_dispatch_request
    rv = self.handle_user_exception(e)
  File "/usr/local/lib/python3.6/dist-packages/flask/app.py", line 1516, in full_dispatch_request
    rv = self.dispatch_request()
  File "/usr/local/lib/python3.6/dist-packages/flask/app.py", line 1502, in dispatch_request
    return self.ensure_sync(self.view_functions[rule.endpoint])(**req.view_args)
  File "/home/jochsankehl/pixelcanvas/1_0/app.py", line 62, in getImageUpdate
    return f'{getImageHash()}|{countVisitors()}'
  File "/home/jochsankehl/pixelcanvas/1_0/app.py", line 118, in countVisitors
    return len(open(visitor_log_filename, 'r').read().strip().split('\n'))
FileNotFoundError: [Errno 2] No such file or directory: 'logs/visitors.log'
ERROR:app:Exception on /imghash [GET]
Traceback (most recent call last):
  File "/usr/local/lib/python3.6/dist-packages/flask/app.py", line 2073, in wsgi_app
    response = self.full_dispatch_request()
  File "/usr/local/lib/python3.6/dist-packages/flask/app.py", line 1518, in full_dispatch_request
    rv = self.handle_user_exception(e)
  File "/usr/local/lib/python3.6/dist-packages/flask/app.py", line 1516, in full_dispatch_request
    rv = self.dispatch_request()
  File "/usr/local/lib/python3.6/dist-packages/flask/app.py", line 1502, in dispatch_request
    return self.ensure_sync(self.view_functions[rule.endpoint])(**req.view_args)
  File "/home/jochsankehl/pixelcanvas/1_0/app.py", line 62, in getImageUpdate
    return f'{getImageHash()}|{countVisitors()}'
  File "/home/jochsankehl/pixelcanvas/1_0/app.py", line 118, in countVisitors
    return len(open(visitor_log_filename, 'r').read().strip().split('\n'))
FileNotFoundError: [Errno 2] No such file or directory: 'logs/visitors.log'
ERROR:app:Exception on /imghash [GET]
Traceback (most recent call last):
  File "/usr/local/lib/python3.6/dist-packages/flask/app.py", line 2073, in wsgi_app
    response = self.full_dispatch_request()
  File "/usr/local/lib/python3.6/dist-packages/flask/app.py", line 1518, in full_dispatch_request
    rv = self.handle_user_exception(e)
  File "/usr/local/lib/python3.6/dist-packages/flask/app.py", line 1516, in full_dispatch_request
    rv = self.dispatch_request()
  File "/usr/local/lib/python3.6/dist-packages/flask/app.py", line 1502, in dispatch_request
    return self.ensure_sync(self.view_functions[rule.endpoint])(**req.view_args)
  File "/home/jochsankehl/pixelcanvas/1_0/app.py", line 62, in getImageUpdate
    return f'{getImageHash()}|{countVisitors()}'
  File "/home/jochsankehl/pixelcanvas/1_0/app.py", line 118, in countVisitors
    return len(open(visitor_log_filename, 'r').read().strip().split('\n'))
FileNotFoundError: [Errno 2] No such file or directory: 'logs/visitors.log'
ERROR:app:Exception on /imghash [GET]
Traceback (most recent call last):
  File "/usr/local/lib/python3.6/dist-packages/flask/app.py", line 2073, in wsgi_app
    response = self.full_dispatch_request()
  File "/usr/local/lib/python3.6/dist-packages/flask/app.py", line 1518, in full_dispatch_request
    rv = self.handle_user_exception(e)
  File "/usr/local/lib/python3.6/dist-packages/flask/app.py", line 1516, in full_dispatch_request
    rv = self.dispatch_request()
  File "/usr/local/lib/python3.6/dist-packages/flask/app.py", line 1502, in dispatch_request
    return self.ensure_sync(self.view_functions[rule.endpoint])(**req.view_args)
  File "/home/jochsankehl/pixelcanvas/1_0/app.py", line 62, in getImageUpdate
    return f'{getImageHash()}|{countVisitors()}'
  File "/home/jochsankehl/pixelcanvas/1_0/app.py", line 118, in countVisitors
    return len(open(visitor_log_filename, 'r').read().strip().split('\n'))
FileNotFoundError: [Errno 2] No such file or directory: 'logs/visitors.log'
ERROR:app:Exception on /imghash [GET]
Traceback (most recent call last):
  File "/usr/local/lib/python3.6/dist-packages/flask/app.py", line 2073, in wsgi_app
    response = self.full_dispatch_request()
  File "/usr/local/lib/python3.6/dist-packages/flask/app.py", line 1518, in full_dispatch_request
    rv = self.handle_user_exception(e)
  File "/usr/local/lib/python3.6/dist-packages/flask/app.py", line 1516, in full_dispatch_request
    rv = self.dispatch_request()
  File "/usr/local/lib/python3.6/dist-packages/flask/app.py", line 1502, in dispatch_request
    return self.ensure_sync(self.view_functions[rule.endpoint])(**req.view_args)
  File "/home/jochsankehl/pixelcanvas/1_0/app.py", line 62, in getImageUpdate
    return f'{getImageHash()}|{countVisitors()}'
  File "/home/jochsankehl/pixelcanvas/1_0/app.py", line 118, in countVisitors
    return len(open(visitor_log_filename, 'r').read().strip().split('\n'))
FileNotFoundError: [Errno 2] No such file or directory: 'logs/visitors.log'
ERROR:app:Exception on /imghash [GET]
Traceback (most recent call last):
  File "/usr/local/lib/python3.6/dist-packages/flask/app.py", line 2073, in wsgi_app
    response = self.full_dispatch_request()
  File "/usr/local/lib/python3.6/dist-packages/flask/app.py", line 1518, in full_dispatch_request
    rv = self.handle_user_exception(e)
  File "/usr/local/lib/python3.6/dist-packages/flask/app.py", line 1516, in full_dispatch_request
    rv = self.dispatch_request()
  File "/usr/local/lib/python3.6/dist-packages/flask/app.py", line 1502, in dispatch_request
    return self.ensure_sync(self.view_functions[rule.endpoint])(**req.view_args)
  File "/home/jochsankehl/pixelcanvas/1_0/app.py", line 62, in getImageUpdate
    return f'{getImageHash()}|{countVisitors()}'
  File "/home/jochsankehl/pixelcanvas/1_0/app.py", line 118, in countVisitors
    return len(open(visitor_log_filename, 'r').read().strip().split('\n'))
FileNotFoundError: [Errno 2] No such file or directory: 'logs/visitors.log'
ERROR:app:Exception on /imghash [GET]
Traceback (most recent call last):
  File "/usr/local/lib/python3.6/dist-packages/flask/app.py", line 2073, in wsgi_app
    response = self.full_dispatch_request()
  File "/usr/local/lib/python3.6/dist-packages/flask/app.py", line 1518, in full_dispatch_request
    rv = self.handle_user_exception(e)
  File "/usr/local/lib/python3.6/dist-packages/flask/app.py", line 1516, in full_dispatch_request
    rv = self.dispatch_request()
  File "/usr/local/lib/python3.6/dist-packages/flask/app.py", line 1502, in dispatch_request
    return self.ensure_sync(self.view_functions[rule.endpoint])(**req.view_args)
  File "/home/jochsankehl/pixelcanvas/1_0/app.py", line 62, in getImageUpdate
    return f'{getImageHash()}|{countVisitors()}'
  File "/home/jochsankehl/pixelcanvas/1_0/app.py", line 118, in countVisitors
    return len(open(visitor_log_filename, 'r').read().strip().split('\n'))
FileNotFoundError: [Errno 2] No such file or directory: 'logs/visitors.log'
ERROR:app:Exception on /imghash [GET]
Traceback (most recent call last):
  File "/usr/local/lib/python3.6/dist-packages/flask/app.py", line 2073, in wsgi_app
    response = self.full_dispatch_request()
  File "/usr/local/lib/python3.6/dist-packages/flask/app.py", line 1518, in full_dispatch_request
    rv = self.handle_user_exception(e)
  File "/usr/local/lib/python3.6/dist-packages/flask/app.py", line 1516, in full_dispatch_request
    rv = self.dispatch_request()
  File "/usr/local/lib/python3.6/dist-packages/flask/app.py", line 1502, in dispatch_request
    return self.ensure_sync(self.view_functions[rule.endpoint])(**req.view_args)
  File "/home/jochsankehl/pixelcanvas/1_0/app.py", line 62, in getImageUpdate
    return f'{getImageHash()}|{countVisitors()}'
  File "/home/jochsankehl/pixelcanvas/1_0/app.py", line 118, in countVisitors
    return len(open(visitor_log_filename, 'r').read().strip().split('\n'))
FileNotFoundError: [Errno 2] No such file or directory: 'logs/visitors.log'
ERROR:app:Exception on /imghash [GET]
Traceback (most recent call last):
  File "/usr/local/lib/python3.6/dist-packages/flask/app.py", line 2073, in wsgi_app
    response = self.full_dispatch_request()
  File "/usr/local/lib/python3.6/dist-packages/flask/app.py", line 1518, in full_dispatch_request
    rv = self.handle_user_exception(e)
  File "/usr/local/lib/python3.6/dist-packages/flask/app.py", line 1516, in full_dispatch_request
    rv = self.dispatch_request()
  File "/usr/local/lib/python3.6/dist-packages/flask/app.py", line 1502, in dispatch_request
    return self.ensure_sync(self.view_functions[rule.endpoint])(**req.view_args)
  File "/home/jochsankehl/pixelcanvas/1_0/app.py", line 62, in getImageUpdate
    return f'{getImageHash()}|{countVisitors()}'
  File "/home/jochsankehl/pixelcanvas/1_0/app.py", line 118, in countVisitors
    return len(open(visitor_log_filename, 'r').read().strip().split('\n'))
FileNotFoundError: [Errno 2] No such file or directory: 'logs/visitors.log'
ERROR:app:Exception on /imghash [GET]
Traceback (most recent call last):
  File "/usr/local/lib/python3.6/dist-packages/flask/app.py", line 2073, in wsgi_app
    response = self.full_dispatch_request()
  File "/usr/local/lib/python3.6/dist-packages/flask/app.py", line 1518, in full_dispatch_request
    rv = self.handle_user_exception(e)
  File "/usr/local/lib/python3.6/dist-packages/flask/app.py", line 1516, in full_dispatch_request
    rv = self.dispatch_request()
  File "/usr/local/lib/python3.6/dist-packages/flask/app.py", line 1502, in dispatch_request
    return self.ensure_sync(self.view_functions[rule.endpoint])(**req.view_args)
  File "/home/jochsankehl/pixelcanvas/1_0/app.py", line 62, in getImageUpdate
    return f'{getImageHash()}|{countVisitors()}'
  File "/home/jochsankehl/pixelcanvas/1_0/app.py", line 118, in countVisitors
    return len(open(visitor_log_filename, 'r').read().strip().split('\n'))
FileNotFoundError: [Errno 2] No such file or directory: 'logs/visitors.log'
ERROR:app:Exception on /imghash [GET]
Traceback (most recent call last):
  File "/usr/local/lib/python3.6/dist-packages/flask/app.py", line 2073, in wsgi_app
    response = self.full_dispatch_request()
  File "/usr/local/lib/python3.6/dist-packages/flask/app.py", line 1518, in full_dispatch_request
    rv = self.handle_user_exception(e)
  File "/usr/local/lib/python3.6/dist-packages/flask/app.py", line 1516, in full_dispatch_request
    rv = self.dispatch_request()
  File "/usr/local/lib/python3.6/dist-packages/flask/app.py", line 1502, in dispatch_request
    return self.ensure_sync(self.view_functions[rule.endpoint])(**req.view_args)
  File "/home/jochsankehl/pixelcanvas/1_0/app.py", line 62, in getImageUpdate
    return f'{getImageHash()}|{countVisitors()}'
  File "/home/jochsankehl/pixelcanvas/1_0/app.py", line 118, in countVisitors
    return len(open(visitor_log_filename, 'r').read().strip().split('\n'))
FileNotFoundError: [Errno 2] No such file or directory: 'logs/visitors.log'
ERROR:app:Exception on /imghash [GET]
Traceback (most recent call last):
  File "/usr/local/lib/python3.6/dist-packages/flask/app.py", line 2073, in wsgi_app
    response = self.full_dispatch_request()
  File "/usr/local/lib/python3.6/dist-packages/flask/app.py", line 1518, in full_dispatch_request
    rv = self.handle_user_exception(e)
  File "/usr/local/lib/python3.6/dist-packages/flask/app.py", line 1516, in full_dispatch_request
    rv = self.dispatch_request()
  File "/usr/local/lib/python3.6/dist-packages/flask/app.py", line 1502, in dispatch_request
    return self.ensure_sync(self.view_functions[rule.endpoint])(**req.view_args)
  File "/home/jochsankehl/pixelcanvas/1_0/app.py", line 62, in getImageUpdate
    return f'{getImageHash()}|{countVisitors()}'
  File "/home/jochsankehl/pixelcanvas/1_0/app.py", line 118, in countVisitors
    return len(open(visitor_log_filename, 'r').read().strip().split('\n'))
FileNotFoundError: [Errno 2] No such file or directory: 'logs/visitors.log'
ERROR:app:Exception on /imghash [GET]
Traceback (most recent call last):
  File "/usr/local/lib/python3.6/dist-packages/flask/app.py", line 2073, in wsgi_app
    response = self.full_dispatch_request()
  File "/usr/local/lib/python3.6/dist-packages/flask/app.py", line 1518, in full_dispatch_request
    rv = self.handle_user_exception(e)
  File "/usr/local/lib/python3.6/dist-packages/flask/app.py", line 1516, in full_dispatch_request
    rv = self.dispatch_request()
  File "/usr/local/lib/python3.6/dist-packages/flask/app.py", line 1502, in dispatch_request
    return self.ensure_sync(self.view_functions[rule.endpoint])(**req.view_args)
  File "/home/jochsankehl/pixelcanvas/1_0/app.py", line 62, in getImageUpdate
    return f'{getImageHash()}|{countVisitors()}'
  File "/home/jochsankehl/pixelcanvas/1_0/app.py", line 118, in countVisitors
    return len(open(visitor_log_filename, 'r').read().strip().split('\n'))
FileNotFoundError: [Errno 2] No such file or directory: 'logs/visitors.log'
ERROR:app:Exception on /imghash [GET]
Traceback (most recent call last):
  File "/usr/local/lib/python3.6/dist-packages/flask/app.py", line 2073, in wsgi_app
    response = self.full_dispatch_request()
  File "/usr/local/lib/python3.6/dist-packages/flask/app.py", line 1518, in full_dispatch_request
    rv = self.handle_user_exception(e)
  File "/usr/local/lib/python3.6/dist-packages/flask/app.py", line 1516, in full_dispatch_request
    rv = self.dispatch_request()
  File "/usr/local/lib/python3.6/dist-packages/flask/app.py", line 1502, in dispatch_request
    return self.ensure_sync(self.view_functions[rule.endpoint])(**req.view_args)
  File "/home/jochsankehl/pixelcanvas/1_0/app.py", line 62, in getImageUpdate
    return f'{getImageHash()}|{countVisitors()}'
  File "/home/jochsankehl/pixelcanvas/1_0/app.py", line 118, in countVisitors
    return len(open(visitor_log_filename, 'r').read().strip().split('\n'))
FileNotFoundError: [Errno 2] No such file or directory: 'logs/visitors.log'
ERROR:app:Exception on /imghash [GET]
Traceback (most recent call last):
  File "/usr/local/lib/python3.6/dist-packages/flask/app.py", line 2073, in wsgi_app
    response = self.full_dispatch_request()
  File "/usr/local/lib/python3.6/dist-packages/flask/app.py", line 1518, in full_dispatch_request
    rv = self.handle_user_exception(e)
  File "/usr/local/lib/python3.6/dist-packages/flask/app.py", line 1516, in full_dispatch_request
    rv = self.dispatch_request()
  File "/usr/local/lib/python3.6/dist-packages/flask/app.py", line 1502, in dispatch_request
    return self.ensure_sync(self.view_functions[rule.endpoint])(**req.view_args)
  File "/home/jochsankehl/pixelcanvas/1_0/app.py", line 62, in getImageUpdate
    return f'{getImageHash()}|{countVisitors()}'
  File "/home/jochsankehl/pixelcanvas/1_0/app.py", line 118, in countVisitors
    return len(open(visitor_log_filename, 'r').read().strip().split('\n'))
FileNotFoundError: [Errno 2] No such file or directory: 'logs/visitors.log'
ERROR:app:Exception on /imghash [GET]
Traceback (most recent call last):
  File "/usr/local/lib/python3.6/dist-packages/flask/app.py", line 2073, in wsgi_app
    response = self.full_dispatch_request()
  File "/usr/local/lib/python3.6/dist-packages/flask/app.py", line 1518, in full_dispatch_request
    rv = self.handle_user_exception(e)
  File "/usr/local/lib/python3.6/dist-packages/flask/app.py", line 1516, in full_dispatch_request
    rv = self.dispatch_request()
  File "/usr/local/lib/python3.6/dist-packages/flask/app.py", line 1502, in dispatch_request
    return self.ensure_sync(self.view_functions[rule.endpoint])(**req.view_args)
  File "/home/jochsankehl/pixelcanvas/1_0/app.py", line 62, in getImageUpdate
    return f'{getImageHash()}|{countVisitors()}'
  File "/home/jochsankehl/pixelcanvas/1_0/app.py", line 118, in countVisitors
    return len(open(visitor_log_filename, 'r').read().strip().split('\n'))
FileNotFoundError: [Errno 2] No such file or directory: 'logs/visitors.log'
